<?xml version="1.0"?>
<robot name="panda_gripper">
  <link name="base_link_x"/>

  <joint name="dummy_x_translation_joint" type="prismatic">
    <parent link="base_link_x"/>
    <child link="base_link_y"/>
    <origin rpy="0 0 0" xyz="0 0 0"/>
    <axis xyz="1 0 0"/>
    <limit effort="300" lower="-10" upper="10" velocity="2.1750"/>
  </joint>

  <link name="base_link_y"/>

  <joint name="dummy_y_translation_joint" type="prismatic">
    <parent link="base_link_y"/>
    <child link="base_link_z"/>
    <origin rpy="0 0 0" xyz="0 0 0"/>
    <axis xyz="0 1 0"/>
    <limit effort="300" lower="-10" upper="10" velocity="2.1750"/>
  </joint>

  <link name="base_link_z"/>

  <joint name="dummy_z_translation_joint" type="prismatic">
    <parent link="base_link_z"/>
    <child link="base_link_roll"/>
    <origin rpy="0 0 0" xyz="0 0 0"/>
    <axis xyz="0 0 1"/>
    <limit effort="300" lower="-10" upper="10" velocity="2.1750"/>
  </joint>

  <link name="base_link_roll"/>

  <joint name="dummy_x_rotation_joint" type="revolute">
    <parent link="base_link_roll"/>
    <child link="base_link_pitch"/>
    <origin rpy="0 0 0" xyz="0 0 0"/>
    <axis xyz="1 0 0"/>
    <limit effort="100.95" velocity="108.48" lower="-6.283185" upper="6.283185"/>
  </joint>

  <link name="base_link_pitch"/>

  <joint name="dummy_y_rotation_joint" type="revolute">
    <parent link="base_link_pitch"/>
    <child link="base_link_yaw"/>
    <origin rpy="0 0 0" xyz="0 0 0"/>
    <axis xyz="0 1 0"/>
    <limit effort="100.95" velocity="108.48" lower="-6.283185" upper="6.283185"/>
  </joint>

  <link name="base_link_yaw"/>

  <joint name="dummy_z_rotation_joint" type="revolute">
    <parent link="base_link_yaw"/>
    <child link="panda_hand"/>
    <origin rpy="0 0 0" xyz="0 0 0"/>
    <axis xyz="0 0 1"/>
    <limit effort="100.95" velocity="108.48" lower="-6.283185" upper="6.283185"/>
  </joint>

  <link name="panda_hand">
    <visual>
      <geometry>
        <mesh filename="meshes/visual/hand.obj"/>
      </geometry>
    </visual>
    <collision>
      <origin rpy="1.570795 0 0" xyz="0 0 0.02617"/>
      <geometry>
        <box size="0.036 0.08 0.2"/>
      </geometry>
    </collision>
    <collision>
      <origin rpy="0 0 0" xyz="0 0 0.0003"/>
      <geometry>
        <cylinder radius="0.03" length="0.0077"/>
      </geometry>
    </collision>
    <inertial>
      <origin rpy="0 0 0" xyz="-0.01 0 0.03"/>
      <mass value="0.73"/>
      <inertia ixx="0.001" ixy="0" ixz="0" iyy="0.0025" iyz="0" izz="0.0017"/>
    </inertial>
  </link>
  <link name="panda_hand_tcp"/>
  <joint name="panda_hand_tcp_joint" type="fixed">
    <origin rpy="0 0 0" xyz="0 0 0.1034"/>
    <parent link="panda_hand"/>
    <child link="panda_hand_tcp"/>
  </joint>
  <link name="panda_leftfinger">
    <visual>
      <geometry>
        <mesh filename="meshes/visual/finger.obj"/>
      </geometry>
    </visual>
    <collision>
      <origin rpy="0 0 0" xyz="0 18.5e-3 11e-3"/>
      <geometry>
        <box size="22e-3 15e-3 20e-3"/>
      </geometry>
    </collision>
    <collision>
      <origin rpy="0 0 0" xyz="0 6.8e-3 2.2e-3"/>
      <geometry>
        <box size="22e-3 8.8e-3 3.8e-3"/>
      </geometry>
    </collision>
    <collision>
      <origin rpy="0.5235987755982988 0 0" xyz="0 15.9e-3 28.35e-3"/>
      <geometry>
        <box size="17.5e-3 7e-3 23.5e-3"/>
      </geometry>
    </collision>
    <collision>
      <origin rpy="0 0 0" xyz="0 7.58e-3 45.25e-3"/>
      <geometry>
        <box size="17.5e-3 15.2e-3 18.5e-3"/>
      </geometry>
    </collision>
    <inertial>
      <origin rpy="0 0 0" xyz="0 0 0"/>
      <mass value="0.015"/>
      <inertia ixx="2.3749999999999997e-06" ixy="0" ixz="0" iyy="2.3749999999999997e-06"
               iyz="0" izz="7.5e-07"/>
    </inertial>
  </link>
  <link name="panda_rightfinger">
    <visual>
      <origin rpy="0 0 3.141592653589793" xyz="0 0 0"/>
      <geometry>
        <mesh filename="meshes/visual/finger.obj"/>
      </geometry>
    </visual>
    <collision>
      <origin rpy="0 0 0" xyz="0 -18.5e-3 11e-3"/>
      <geometry>
        <box size="22e-3 15e-3 20e-3"/>
      </geometry>
    </collision>
    <collision>
      <origin rpy="0 0 0" xyz="0 -6.8e-3 2.2e-3"/>
      <geometry>
        <box size="22e-3 8.8e-3 3.8e-3"/>
      </geometry>
    </collision>
    <collision>
      <origin rpy="-0.5235987755982988 0 0" xyz="0 -15.9e-3 28.35e-3"/>
      <geometry>
        <box size="17.5e-3 7e-3 23.5e-3"/>
      </geometry>
    </collision>
    <collision>
      <origin rpy="0 0 0" xyz="0 -7.58e-3 45.25e-3"/>
      <geometry>
        <box size="17.5e-3 15.2e-3 18.5e-3"/>
      </geometry>
    </collision>
    <inertial>
      <origin rpy="0 0 0" xyz="0 0 0"/>
      <mass value="0.015"/>
      <inertia ixx="2.3749999999999997e-06" ixy="0" ixz="0" iyy="2.3749999999999997e-06"
               iyz="0" izz="7.5e-07"/>
    </inertial>
  </link>
  <joint name="panda_finger_joint1" type="prismatic">
    <parent link="panda_hand"/>
    <child link="panda_leftfinger"/>
    <origin rpy="0 0 0" xyz="0 0 0.0584"/>
    <axis xyz="0 1 0"/>
    <limit effort="100" lower="0.0" upper="0.04" velocity="0.2"/>
    <dynamics damping="0.3"/>
  </joint>
  <joint name="panda_finger_joint2" type="prismatic">
    <parent link="panda_hand"/>
    <child link="panda_rightfinger"/>
    <origin rpy="0 0 0" xyz="0 0 0.0584"/>
    <axis xyz="0 -1 0"/>
    <limit effort="100" lower="0.0" upper="0.04" velocity="0.2"/>
    <mimic joint="panda_finger_joint1" multiplier="1" offset="0"/>
    <dynamics damping="0.3"/>
  </joint>
</robot>
